<?xml version="1.0"?>
<robot name="delivery_bot" xmlns:xacro="http://ros.org/wiki/xacro">

  <!-- Chassis -->
  <link name="base_link">
    <visual>
      <geometry>
        <box size="0.4 0.3 0.1"/>
      </geometry>
      <origin xyz="0 0 0.05" rpy="0 0 0"/>
      <material name="grey">
        <color rgba="0.6 0.6 0.6 1.0"/>
      </material>
    </visual>
  </link>

  <!-- LIDAR -->
  <link name="laser_link">
    <visual>
      <geometry>
        <cylinder length="0.05" radius="0.04"/>
      </geometry>
      <origin xyz="0 0 0" rpy="0 0 0"/>
      <material name="black">
        <color rgba="0.1 0.1 0.1 1.0"/>
      </material>
    </visual>
  </link>

  <joint name="laser_joint" type="fixed">
    <parent link="base_link"/>
    <child link="laser_link"/>
    <origin xyz="0 0 0.15" rpy="0 0 0"/>
  </joint>

  <!-- Wheels -->
  <!-- Left Front -->
  <link name="left_front_wheel">
    <visual>
      <geometry>
        <cylinder radius="0.04" length="0.02"/>
      </geometry>
      <origin xyz="0 0 0" rpy="1.5708 0 0"/>
      <material name="black"/>
    </visual>
  </link>
  <joint name="left_front_joint" type="continuous">
    <parent link="base_link"/>
    <child link="left_front_wheel"/>
    <origin xyz="0.15 0.13 0.02" rpy="0 0 0"/>
    <axis xyz="0 1 0"/>
  </joint>

  <!-- Left Rear -->
  <link name="left_rear_wheel">
    <visual>
      <geometry>
        <cylinder radius="0.04" length="0.02"/>
      </geometry>
      <origin xyz="0 0 0" rpy="1.5708 0 0"/>
      <material name="black"/>
    </visual>
  </link>
  <joint name="left_rear_joint" type="continuous">
    <parent link="base_link"/>
    <child link="left_rear_wheel"/>
    <origin xyz="-0.15 0.13 0.02" rpy="0 0 0"/>
    <axis xyz="0 1 0"/>
  </joint>

  <!-- Right Front -->
  <link name="right_front_wheel">
    <visual>
      <geometry>
        <cylinder radius="0.04" length="0.02"/>
      </geometry>
      <origin xyz="0 0 0" rpy="1.5708 0 0"/>
      <material name="black"/>
    </visual>
  </link>
  <joint name="right_front_joint" type="continuous">
    <parent link="base_link"/>
    <child link="right_front_wheel"/>
    <origin xyz="0.15 -0.13 0.02" rpy="0 0 0"/>
    <axis xyz="0 1 0"/>
  </joint>

  <!-- Right Rear -->
  <link name="right_rear_wheel">
    <visual>
      <geometry>
        <cylinder radius="0.04" length="0.02"/>
      </geometry>
      <origin xyz="0 0 0" rpy="1.5708 0 0"/>
      <material name="black"/>
    </visual>
  </link>
  <joint name="right_rear_joint" type="continuous">
    <parent link="base_link"/>
    <child link="right_rear_wheel"/>
    <origin xyz="-0.15 -0.13 0.02" rpy="0 0 0"/>
    <axis xyz="0 1 0"/>
  </joint>

</robot>
